Workbook

Sheet RELATÓRIO DE VENDAS
A1: Cód. | B1: Cliente | C1: CIDADE | D1: UF | E1: LOCALIZAÇÃO | F1: DATA2 | G1: Valor custo | H1: Valor total | I1: MARGEM BRUTA | J1: %MARGEM BRUTA | K1: CLASSIFICAÇÃO | L1: BAIRRO
A2: 3708 | B2: E L FRAGNAN SERRALHERIA E SERVICOS EIRELI | C2: =VLOOKUP(Tabela1[[#This Row],[Cliente]],'BASE DE CLIENTES'!A:E,2,0) -> Brasília | D2: =VLOOKUP(Tabela1[[#This Row],[Cliente]],'BASE DE CLIENTES'!A:C,3,0) -> DF | E2: =CONCATENATE(Tabela1[[#This Row],[CIDADE]],",",Tabela1[[#This Row],[UF]]) -> Brasília,DF | F2: 45688 | G2: 811.63 | H2: 1750 | I2: =Tabela1[[#This Row],[Valor total]]-Tabela1[[#This Row],[Valor custo]] -> 938.37 | J2: =Tabela1[[#This Row],[MARGEM BRUTA]]/Tabela1[[#This Row],[Valor total]] -> 0.53621143 | K2: =VLOOKUP(Tabela1[[#This Row],[Cliente]],'BASE DE CLIENTES'!A:D,4,0) -> EMPRESA COM MAQUINA | L2: =VLOOKUP(Tabela1[[#This Row],[Cliente]],'BASE DE CLIENTES'!A:E,5,0) -> CANDANGOLANDIA
A3: 3707 | B3: 25.157.978 FERNANDA CRISTINA SOUZA DA SILVA | C3: =VLOOKUP(Tabela1[[#This Row],[Cliente]],'BASE DE CLIENTES'!A:E,2,0) -> Brasília | D3: =VLOOKUP(Tabela1[[#This Row],[Cliente]],'BASE DE CLIENTES'!A:C,3,0) -> DF | E3: =CONCATENATE(Tabela1[[#This Row],[CIDADE]],",",Tabela1[[#This Row],[UF]]) -> Brasília,DF | F3: 45688 | G3: 104.4 | H3: 364.6 | I3: =Tabela1[[#This Row],[Valor total]]-Tabela1[[#This Row],[Valor custo]] -> 260.2 | J3: =Tabela1[[#This Row],[MARGEM BRUTA]]/Tabela1[[#This Row],[Valor total]] -> 0.7136588 | K3: =VLOOKUP(Tabela1[[#This Row],[Cliente]],'BASE DE CLIENTES'!A:D,4,0) -> SERRALHEIRO | L3: =VLOOKUP(Tabela1[[#This Row],[Cliente]],'BASE DE CLIENTES'!A:E,5,0) -> SETOR HABITACIONAL VICENTE PIRES
A4: 3675 | B4: RONALDO ADRIANO DA SILVA SOLSA | C4: =VLOOKUP(Tabela1[[#This Row],[Cliente]],'BASE DE CLIENTES'!A:E,2,0) -> Águas Lindas de Goiás | D4: =VLOOKUP(Tabela1[[#This Row],[Cliente]],'BASE DE CLIENTES'!A:C,3,0) -> GO | E4: =CONCATENATE(Tabela1[[#This Row],[CIDADE]],",",Tabela1[[#This Row],[UF]]) -> Águas Lindas de Goiás,GO | F4: 45686 | G4: 514.45 | H4: 805 | I4: =Tabela1[[#This Row],[Valor total]]-Tabela1[[#This Row],[Valor custo]] -> 290.55 | J4: =Tabela1[[#This Row],[MARGEM BRUTA]]/Tabela1[[#This Row],[Valor total]] -> 0.36093168 | K4: =VLOOKUP(Tabela1[[#This Row],[Cliente]],'BASE DE CLIENTES'!A:D,4,0) -> SERRALHEIRO | L4: =VLOOKUP(Tabela1[[#This Row],[Cliente]],'BASE DE CLIENTES'!A:E,5,0) -> Águas Lindas de Goiás
A5: 3661 | B5: MARIO APARECIDO PEREIRA DE BRITO | C5: =VLOOKUP(Tabela1[[#This Row],[Cliente]],'BASE DE CLIENTES'!A:E,2,0) -> Águas Lindas de Goiás | D5: =VLOOKUP(Tabela1[[#This Row],[Cliente]],'BASE DE CLIENTES'!A:C,3,0) -> GO | E5: =CONCATENATE(Tabela1[[#This Row],[CIDADE]],",",Tabela1[[#This Row],[UF]]) -> Águas Lindas de Goiás,GO | F5: 45684 | G5: 25.94 | H5: 40 | I5: =Tabela1[[#This Row],[Valor total]]-Tabela1[[#This Row],[Valor custo]] -> 14.06 | J5: =Tabela1[[#This Row],[MARGEM BRUTA]]/Tabela1[[#This Row],[Valor total]] -> 0.3515 | K5: =VLOOKUP(Tabela1[[#This Row],[Cliente]],'BASE DE CLIENTES'!A:D,4,0) -> SERRALHEIRO | L5: =VLOOKUP(Tabela1[[#This Row],[Cliente]],'BASE DE CLIENTES'!A:E,5,0) -> Águas Lindas de Goiás
B6: CHAVEIRO MARCOS ÁGUAS CLARAS | C6: =VLOOKUP(Tabela1[[#This Row],[Cliente]],'BASE DE CLIENTES'!A:E,2,0) -> Brasília | D6: =VLOOKUP(Tabela1[[#This Row],[Cliente]],'BASE DE CLIENTES'!A:C,3,0) -> DF | E6: =CONCATENATE(Tabela1[[#This Row],[CIDADE]],",",Tabela1[[#This Row],[UF]]) -> Brasília,DF | F6: 45892 | G6: 293.13 | H6: 450 | I6: =Tabela1[[#This Row],[Valor total]]-Tabela1[[#This Row],[Valor custo]] -> 156.87 | J6: =Tabela1[[#This Row],[MARGEM BRUTA]]/Tabela1[[#This Row],[Valor total]] -> 0.3486 | K6: =VLOOKUP(Tabela1[[#This Row],[Cliente]],'BASE DE CLIENTES'!A:D,4,0) -> CHAVEIRO | L6: =VLOOKUP(Tabela1[[#This Row],[Cliente]],'BASE DE CLIENTES'!A:E,5,0) -> NA
B7: DILMAR PEREIRA DE SOUZA | C7: =VLOOKUP(Tabela1[[#This Row],[Cliente]],'BASE DE CLIENTES'!A:E,2,0) -> Brasília | D7: =VLOOKUP(Tabela1[[#This Row],[Cliente]],'BASE DE CLIENTES'!A:C,3,0) -> DF | E7: =CONCATENATE(Tabela1[[#This Row],[CIDADE]],",",Tabela1[[#This Row],[UF]]) -> Brasília,DF | F7: 45736 | G7: 9078.3 | H7: 13375 | I7: =Tabela1[[#This Row],[Valor total]]-Tabela1[[#This Row],[Valor custo]] -> 4296.7 | J7: =Tabela1[[#This Row],[MARGEM BRUTA]]/Tabela1[[#This Row],[Valor total]] -> 0.3212486 | K7: =VLOOKUP(Tabela1[[#This Row],[Cliente]],'BASE DE CLIENTES'!A:D,4,0) -> EMPRESA COM MAQUINA | L7: =VLOOKUP(Tabela1[[#This Row],[Cliente]],'BASE DE CLIENTES'!A:E,5,0) -> RIACHO FUNDO II
A8: 3702 | B8: ACOFER METALURGICA E COMERCIO LTDA | C8: =VLOOKUP(Tabela1[[#This Row],[Cliente]],'BASE DE CLIENTES'!A:E,2,0) -> Brasília | D8: =VLOOKUP(Tabela1[[#This Row],[Cliente]],'BASE DE CLIENTES'!A:C,3,0) -> DF | E8: =CONCATENATE(Tabela1[[#This Row],[CIDADE]],",",Tabela1[[#This Row],[UF]]) -> Brasília,DF | F8: 45688 | G8: 878.4 | H8: 1320 | I8: =Tabela1[[#This Row],[Valor total]]-Tabela1[[#This Row],[Valor custo]] -> 441.6 | J8: =Tabela1[[#This Row],[MARGEM BRUTA]]/Tabela1[[#This Row],[Valor total]] -> 0.33454545 | K8: =VLOOKUP(Tabela1[[#This Row],[Cliente]],'BASE DE CLIENTES'!A:D,4,0) -> EMPRESA SEM MAQUINA | L8: =VLOOKUP(Tabela1[[#This Row],[Cliente]],'BASE DE CLIENTES'!A:E,5,0) -> SETOR INDUSTRIAL (TAGUATINGA)
A9: 3701 | B9: CENTRAL PORTAS DE ACO AUTOMATICAS LTDA | C9: =VLOOKUP(Tabela1[[#This Row],[Cliente]],'BASE DE CLIENTES'!A:E,2,0) -> Brasília | D9: =VLOOKUP(Tabela1[[#This Row],[Cliente]],'BASE DE CLIENTES'!A:C,3,0) -> DF | E9: =CONCATENATE(Tabela1[[#This Row],[CIDADE]],",",Tabela1[[#This Row],[UF]]) -> Brasília,DF | F9: 45688 | G9: 39.87 | H9: 60 | I9: =Tabela1[[#This Row],[Valor total]]-Tabela1[[#This Row],[Valor custo]] -> 20.13 | J9: =Tabela1[[#This Row],[MARGEM BRUTA]]/Tabela1[[#This Row],[Valor total]] -> 0.3355 | K9: =VLOOKUP(Tabela1[[#This Row],[Cliente]],'BASE DE CLIENTES'!A:D,4,0) -> EMPRESA COM MAQUINA | L9: =VLOOKUP(Tabela1[[#This Row],[Cliente]],'BASE DE CLIENTES'!A:E,5,0) -> CEILANDIA NORTE (CEILANDIA)
A10: 3700 | B10: 34.505.918 JOSE ANTONIO DUTRA DA SILVA | C10: =VLOOKUP(Tabela1[[#This Row],[Cliente]],'BASE DE CLIENTES'!A:E,2,0) -> Brasília | D10: =VLOOKUP(Tabela1[[#This Row],[Cliente]],'BASE DE CLIENTES'!A:C,3,0) -> DF | E10: =CONCATENATE(Tabela1[[#This Row],[CIDADE]],",",Tabela1[[#This Row],[UF]]) -> Brasília,DF | F10: 45688 | G10: 857.96 | H10: 1700 | I10: =Tabela1[[#This Row],[Valor total]]-Tabela1[[#This Row],[Valor custo]] -> 842.04 | J10: =Tabela1[[#This Row],[MARGEM BRUTA]]/Tabela1[[#This Row],[Valor total]] -> 0.49531765 | K10: =VLOOKUP(Tabela1[[#This Row],[Cliente]],'BASE DE CLIENTES'!A:D,4,0) -> EMPRESA SEM MAQUINA | L10: =VLOOKUP(Tabela1[[#This Row],[Cliente]],'BASE DE CLIENTES'!A:E,5,0) -> RECANTO DAS EMAS
A11: 3699 | B11: CENTRAL PORTAS DE ACO AUTOMATICAS LTDA | C11: =VLOOKUP(Tabela1[[#This Row],[Cliente]],'BASE DE CLIENTES'!A:E,2,0) -> Brasília | D11: =VLOOKUP(Tabela1[[#This Row],[Cliente]],'BASE DE CLIENTES'!A:C,3,0) -> DF | E11: =CONCATENATE(Tabela1[[#This Row],[CIDADE]],",",Tabela1[[#This Row],[UF]]) -> Brasília,DF | F11: 45688 | G11: 1764.47 | H11: 2855 | I11: =Tabela1[[#This Row],[Valor total]]-Tabela1[[#This Row],[Valor custo]] -> 1090.53 | J11: =Tabela1[[#This Row],[MARGEM BRUTA]]/Tabela1[[#This Row],[Valor total]] -> 0.38197198 | K11: =VLOOKUP(Tabela1[[#This Row],[Cliente]],'BASE DE CLIENTES'!A:D,4,0) -> EMPRESA COM MAQUINA | L11: =VLOOKUP(Tabela1[[#This Row],[Cliente]],'BASE DE CLIENTES'!A:E,5,0) -> CEILANDIA NORTE (CEILANDIA)
A12: 3657 | B12: Gefferson de Amorim | C12: =VLOOKUP(Tabela1[[#This Row],[Cliente]],'BASE DE CLIENTES'!A:E,2,0) -> Águas Lindas de Goiás | D12: =VLOOKUP(Tabela1[[#This Row],[Cliente]],'BASE DE CLIENTES'!A:C,3,0) -> GO | E12: =CONCATENATE(Tabela1[[#This Row],[CIDADE]],",",Tabela1[[#This Row],[UF]]) -> Águas Lindas de Goiás,GO | F12: 45684 | G12: 1187.66 | H12: 2050 | I12: =Tabela1[[#This Row],[Valor total]]-Tabela1[[#This Row],[Valor custo]] -> 862.34 | J12: =Tabela1[[#This Row],[MARGEM BRUTA]]/Tabela1[[#This Row],[Valor total]] -> 0.42065366 | K12: =VLOOKUP(Tabela1[[#This Row],[Cliente]],'BASE DE CLIENTES'!A:D,4,0) -> SERRALHEIRO | L12: =VLOOKUP(Tabela1[[#This Row],[Cliente]],'BASE DE CLIENTES'!A:E,5,0) -> Águas Lindas de Goiás
A13: 3644 | B13: RONALDO ADRIANO DA SILVA SOLSA | C13: =VLOOKUP(Tabela1[[#This Row],[Cliente]],'BASE DE CLIENTES'!A:E,2,0) -> Águas Lindas de Goiás | D13: =VLOOKUP(Tabela1[[#This Row],[Cliente]],'BASE DE CLIENTES'!A:C,3,0) -> GO | E13: =CONCATENATE(Tabela1[[#This Row],[CIDADE]],",",Tabela1[[#This Row],[UF]]) -> Águas Lindas de Goiás,GO | F13: 45681 | G13: 1317.6 | H13: 1935 | I13: =Tabela1[[#This Row],[Valor total]]-Tabela1[[#This Row],[Valor custo]] -> 617.4 | J13: =Tabela1[[#This Row],[MARGEM BRUTA]]/Tabela1[[#This Row],[Valor total]] -> 0.31906977 | K13: =VLOOKUP(Tabela1[[#This Row],[Cliente]],'BASE DE CLIENTES'!A:D,4,0) -> SERRALHEIRO | L13: =VLOOKUP(Tabela1[[#This Row],[Cliente]],'BASE DE CLIENTES'!A:E,5,0) -> Águas Lindas de Goiás
A14: 3631 | B14: Gefferson de Amorim | C14: =VLOOKUP(Tabela1[[#This Row],[Cliente]],'BASE DE CLIENTES'!A:E,2,0) -> Águas Lindas de Goiás | D14: =VLOOKUP(Tabela1[[#This Row],[Cliente]],'BASE DE CLIENTES'!A:C,3,0) -> GO | E14: =CONCATENATE(Tabela1[[#This Row],[CIDADE]],",",Tabela1[[#This Row],[UF]]) -> Águas Lindas de Goiás,GO | F14: 45680 | G14: 514.45 | H14: 720 | I14: =Tabela1[[#This Row],[Valor total]]-Tabela1[[#This Row],[Valor custo]] -> 205.55 | J14: =Tabela1[[#This Row],[MARGEM BRUTA]]/Tabela1[[#This Row],[Valor total]] -> 0.28548611 | K14: =VLOOKUP(Tabela1[[#This Row],[Cliente]],'BASE DE CLIENTES'!A:D,4,0) -> SERRALHEIRO | L14: =VLOOKUP(Tabela1[[#This Row],[Cliente]],'BASE DE CLIENTES'!A:E,5,0) -> Águas Lindas de Goiás
B15: Gefferson de Amorim | C15: =VLOOKUP(Tabela1[[#This Row],[Cliente]],'BASE DE CLIENTES'!A:E,2,0) -> Águas Lindas de Goiás | D15: =VLOOKUP(Tabela1[[#This Row],[Cliente]],'BASE DE CLIENTES'!A:C,3,0) -> GO | E15: =CONCATENATE(Tabela1[[#This Row],[CIDADE]],",",Tabela1[[#This Row],[UF]]) -> Águas Lindas de Goiás,GO | F15: 45678 | G15: 439.2 | H15: 645 | I15: =Tabela1[[#This Row],[Valor total]]-Tabela1[[#This Row],[Valor custo]] -> 205.8 | J15: =Tabela1[[#This Row],[MARGEM BRUTA]]/Tabela1[[#This Row],[Valor total]] -> 0.31906977 | K15: =VLOOKUP(Tabela1[[#This Row],[Cliente]],'BASE DE CLIENTES'!A:D,4,0) -> SERRALHEIRO | L15: =VLOOKUP(Tabela1[[#This Row],[Cliente]],'BASE DE CLIENTES'!A:E,5,0) -> Águas Lindas de Goiás
B16: MARIO APARECIDO PEREIRA DE BRITO | C16: =VLOOKUP(Tabela1[[#This Row],[Cliente]],'BASE DE CLIENTES'!A:E,2,0) -> Águas Lindas de Goiás | D16: =VLOOKUP(Tabela1[[#This Row],[Cliente]],'BASE DE CLIENTES'!A:C,3,0) -> GO | E16: =CONCATENATE(Tabela1[[#This Row],[CIDADE]],",",Tabela1[[#This Row],[UF]]) -> Águas Lindas de Goiás,GO | F16: 45673 | G16: 20.88 | H16: 90 | I16: =Tabela1[[#This Row],[Valor total]]-Tabela1[[#This Row],[Valor custo]] -> 69.12 | J16: =Tabela1[[#This Row],[MARGEM BRUTA]]/Tabela1[[#This Row],[Valor total]] -> 0.768 | K16: =VLOOKUP(Tabela1[[#This Row],[Cliente]],'BASE DE CLIENTES'!A:D,4,0) -> SERRALHEIRO | L16: =VLOOKUP(Tabela1[[#This Row],[Cliente]],'BASE DE CLIENTES'!A:E,5,0) -> Águas Lindas de Goiás
A17: 3693 | B17: 19.488.372 EZEQUIEL DE FREITAS CARNEIRO | C17: =VLOOKUP(Tabela1[[#This Row],[Cliente]],'BASE DE CLIENTES'!A:E,2,0) -> Brasília | D17: =VLOOKUP(Tabela1[[#This Row],[Cliente]],'BASE DE CLIENTES'!A:C,3,0) -> DF | E17: =CONCATENATE(Tabela1[[#This Row],[CIDADE]],",",Tabela1[[#This Row],[UF]]) -> Brasília,DF | F17: 45688 | G17: 514.45 | H17: 741.6 | I17: =Tabela1[[#This Row],[Valor total]]-Tabela1[[#This Row],[Valor custo]] -> 227.15 | J17: =Tabela1[[#This Row],[MARGEM BRUTA]]/Tabela1[[#This Row],[Valor total]] -> 0.3062972 | K17: =VLOOKUP(Tabela1[[#This Row],[Cliente]],'BASE DE CLIENTES'!A:D,4,0) -> SERRALHEIRO | L17: =VLOOKUP(Tabela1[[#This Row],[Cliente]],'BASE DE CLIENTES'!A:E,5,0) -> RECANTO DAS EMAS
A18: 3692 | B18: WILSON JOSE RODRIGUES JUNIOR 69748209172 | C18: =VLOOKUP(Tabela1[[#This Row],[Cliente]],'BASE DE CLIENTES'!A:E,2,0) -> Brasília | D18: =VLOOKUP(Tabela1[[#This Row],[Cliente]],'BASE DE CLIENTES'!A:C,3,0) -> DF | E18: =CONCATENATE(Tabela1[[#This Row],[CIDADE]],",",Tabela1[[#This Row],[UF]]) -> Brasília,DF | F18: 45688 | G18: 514.45 | H18: 720 | I18: =Tabela1[[#This Row],[Valor total]]-Tabela1[[#This Row],[Valor custo]] -> 205.55 | J18: =Tabela1[[#This Row],[MARGEM BRUTA]]/Tabela1[[#This Row],[Valor total]] -> 0.28548611 | K18: =VLOOKUP(Tabela1[[#This Row],[Cliente]],'BASE DE CLIENTES'!A:D,4,0) -> SERRALHEIRO | L18: =VLOOKUP(Tabela1[[#This Row],[Cliente]],'BASE DE CLIENTES'!A:E,5,0) -> CEILANDIA SUL (CEILANDIA)
A19: 3691 | B19: EDIVALDO FERNANDES DA SILVA 00098636138 | C19: =VLOOKUP(Tabela1[[#This Row],[Cliente]],'BASE DE CLIENTES'!A:E,2,0) -> Brasília | D19: =VLOOKUP(Tabela1[[#This Row],[Cliente]],'BASE DE CLIENTES'!A:C,3,0) -> DF | E19: =CONCATENATE(Tabela1[[#This Row],[CIDADE]],",",Tabela1[[#This Row],[UF]]) -> Brasília,DF | F19: 45688 | G19: 77.82 | H19: 108 | I19: =Tabela1[[#This Row],[Valor total]]-Tabela1[[#This Row],[Valor custo]] -> 30.18 | J19: =Tabela1[[#This Row],[MARGEM BRUTA]]/Tabela1[[#This Row],[Valor total]] -> 0.27944444 | K19: =VLOOKUP(Tabela1[[#This Row],[Cliente]],'BASE DE CLIENTES'!A:D,4,0) -> EMPRESA SEM MAQUINA | L19: =VLOOKUP(Tabela1[[#This Row],[Cliente]],'BASE DE CLIENTES'!A:E,5,0) -> PONTE ALTA NORTE (GAMA)
A20: 3690 | B20: EDIVALDO FERNANDES DA SILVA 00098636138 | C20: =VLOOKUP(Tabela1[[#This Row],[Cliente]],'BASE DE CLIENTES'!A:E,2,0) -> Brasília | D20: =VLOOKUP(Tabela1[[#This Row],[Cliente]],'BASE DE CLIENTES'!A:C,3,0) -> DF | E20: =CONCATENATE(Tabela1[[#This Row],[CIDADE]],",",Tabela1[[#This Row],[UF]]) -> Brasília,DF | F20: 45688 | G20: 62.75 | H20: 70 | I20: =Tabela1[[#This Row],[Valor total]]-Tabela1[[#This Row],[Valor custo]] -> 7.25 | J20: =Tabela1[[#This Row],[MARGEM BRUTA]]/Tabela1[[#This Row],[Valor total]] -> 0.10357143 | K20: =VLOOKUP(Tabela1[[#This Row],[Cliente]],'BASE DE CLIENTES'!A:D,4,0) -> EMPRESA SEM MAQUINA | L20: =VLOOKUP(Tabela1[[#This Row],[Cliente]],'BASE DE CLIENTES'!A:E,5,0) -> PONTE ALTA NORTE (GAMA)
A21: 3688 | B21: EDIVALDO FERNANDES DA SILVA 00098636138 | C21: =VLOOKUP(Tabela1[[#This Row],[Cliente]],'BASE DE CLIENTES'!A:E,2,0) -> Brasília | D21: =VLOOKUP(Tabela1[[#This Row],[Cliente]],'BASE DE CLIENTES'!A:C,3,0) -> DF | E21: =CONCATENATE(Tabela1[[#This Row],[CIDADE]],",",Tabela1[[#This Row],[UF]]) -> Brasília,DF | F21: 45688 | G21: 718.57 | H21: 1250 | I21: =Tabela1[[#This Row],[Valor total]]-Tabela1[[#This Row],[Valor custo]] -> 531.43 | J21: =Tabela1[[#This Row],[MARGEM BRUTA]]/Tabela1[[#This Row],[Valor total]] -> 0.425144 | K21: =VLOOKUP(Tabela1[[#This Row],[Cliente]],'BASE DE CLIENTES'!A:D,4,0) -> EMPRESA SEM MAQUINA | L21: =VLOOKUP(Tabela1[[#This Row],[Cliente]],'BASE DE CLIENTES'!A:E,5,0) -> PONTE ALTA NORTE (GAMA)
B22: MARIO APARECIDO PEREIRA DE BRITO | C22: =VLOOKUP(Tabela1[[#This Row],[Cliente]],'BASE DE CLIENTES'!A:E,2,0) -> Águas Lindas de Goiás | D22: =VLOOKUP(Tabela1[[#This Row],[Cliente]],'BASE DE CLIENTES'!A:C,3,0) -> GO | E22: =CONCATENATE(Tabela1[[#This Row],[CIDADE]],",",Tabela1[[#This Row],[UF]]) -> Águas Lindas de Goiás,GO | F22: 45671 | G22: 1594.35 | H22: 2355 | I22: =Tabela1[[#This Row],[Valor total]]-Tabela1[[#This Row],[Valor custo]] -> 760.65 | J22: =Tabela1[[#This Row],[MARGEM BRUTA]]/Tabela1[[#This Row],[Valor total]] -> 0.32299363 | K22: =VLOOKUP(Tabela1[[#This Row],[Cliente]],'BASE DE CLIENTES'!A:D,4,0) -> SERRALHEIRO | L22: =VLOOKUP(Tabela1[[#This Row],[Cliente]],'BASE DE CLIENTES'!A:E,5,0) -> Águas Lindas de Goiás
A23: 3686 | B23: JM PORTAS AUTOMATICAS LTDA | C23: =VLOOKUP(Tabela1[[#This Row],[Cliente]],'BASE DE CLIENTES'!A:E,2,0) -> Brasília | D23: =VLOOKUP(Tabela1[[#This Row],[Cliente]],'BASE DE CLIENTES'!A:C,3,0) -> DF | E23: =CONCATENATE(Tabela1[[#This Row],[CIDADE]],",",Tabela1[[#This Row],[UF]]) -> Brasília,DF | F23: 45688 | G23: 543.6 | H23: 970 | I23: =Tabela1[[#This Row],[Valor total]]-Tabela1[[#This Row],[Valor custo]] -> 426.4 | J23: =Tabela1[[#This Row],[MARGEM BRUTA]]/Tabela1[[#This Row],[Valor total]] -> 0.43958763 | K23: =VLOOKUP(Tabela1[[#This Row],[Cliente]],'BASE DE CLIENTES'!A:D,4,0) -> EMPRESA SEM MAQUINA | L23: =VLOOKUP(Tabela1[[#This Row],[Cliente]],'BASE DE CLIENTES'!A:E,5,0) -> SAMAMBAIA
A24: 3685 | B24: JAIME FRANCISCO SOARES 27103323100 | C24: =VLOOKUP(Tabela1[[#This Row],[Cliente]],'BASE DE CLIENTES'!A:E,2,0) -> Brasília | D24: =VLOOKUP(Tabela1[[#This Row],[Cliente]],'BASE DE CLIENTES'!A:C,3,0) -> DF | E24: =CONCATENATE(Tabela1[[#This Row],[CIDADE]],",",Tabela1[[#This Row],[UF]]) -> Brasília,DF | F24: 45687 | G24: 52.2 | H24: 185 | I24: =Tabela1[[#This Row],[Valor total]]-Tabela1[[#This Row],[Valor custo]] -> 132.8 | J24: =Tabela1[[#This Row],[MARGEM BRUTA]]/Tabela1[[#This Row],[Valor total]] -> 0.71783784 | K24: =VLOOKUP(Tabela1[[#This Row],[Cliente]],'BASE DE CLIENTES'!A:D,4,0) -> EMPRESA SEM MAQUINA | L24: =VLOOKUP(Tabela1[[#This Row],[Cliente]],'BASE DE CLIENTES'!A:E,5,0) -> SETOR HABITACIONAL VICENTE PIRES
A25: 3684 | B25: 34.505.918 JOSE ANTONIO DUTRA DA SILVA | C25: =VLOOKUP(Tabela1[[#This Row],[Cliente]],'BASE DE CLIENTES'!A:E,2,0) -> Brasília | D25: =VLOOKUP(Tabela1[[#This Row],[Cliente]],'BASE DE CLIENTES'!A:C,3,0) -> DF | E25: =CONCATENATE(Tabela1[[#This Row],[CIDADE]],",",Tabela1[[#This Row],[UF]]) -> Brasília,DF | F25: 45687 | G25: 903.4 | H25: 1270 | I25: =Tabela1[[#This Row],[Valor total]]-Tabela1[[#This Row],[Valor custo]] -> 366.6 | J25: =Tabela1[[#This Row],[MARGEM BRUTA]]/Tabela1[[#This Row],[Valor total]] -> 0.28866142 | K25: =VLOOKUP(Tabela1[[#This Row],[Cliente]],'BASE DE CLIENTES'!A:D,4,0) -> EMPRESA SEM MAQUINA | L25: =VLOOKUP(Tabela1[[#This Row],[Cliente]],'BASE DE CLIENTES'!A:E,5,0) -> RECANTO DAS EMAS
A26: 3683 | B26: CENTRAL PORTAS DE ACO AUTOMATICAS LTDA | C26: =VLOOKUP(Tabela1[[#This Row],[Cliente]],'BASE DE CLIENTES'!A:E,2,0) -> Brasília | D26: =VLOOKUP(Tabela1[[#This Row],[Cliente]],'BASE DE CLIENTES'!A:C,3,0) -> DF | E26: =CONCATENATE(Tabela1[[#This Row],[CIDADE]],",",Tabela1[[#This Row],[UF]]) -> Brasília,DF | F26: 45687 | G26: 514.45 | H26: 720 | I26: =Tabela1[[#This Row],[Valor total]]-Tabela1[[#This Row],[Valor custo]] -> 205.55 | J26: =Tabela1[[#This Row],[MARGEM BRUTA]]/Tabela1[[#This Row],[Valor total]] -> 0.28548611 | K26: =VLOOKUP(Tabela1[[#This Row],[Cliente]],'BASE DE CLIENTES'!A:D,4,0) -> EMPRESA COM MAQUINA | L26: =VLOOKUP(Tabela1[[#This Row],[Cliente]],'BASE DE CLIENTES'!A:E,5,0) -> CEILANDIA NORTE (CEILANDIA)
A27: 3682 | B27: ACOFER METALURGICA E COMERCIO LTDA | C27: =VLOOKUP(Tabela1[[#This Row],[Cliente]],'BASE DE CLIENTES'!A:E,2,0) -> Brasília | D27: =VLOOKUP(Tabela1[[#This Row],[Cliente]],'BASE DE CLIENTES'!A:C,3,0) -> DF | E27: =CONCATENATE(Tabela1[[#This Row],[CIDADE]],",",Tabela1[[#This Row],[UF]]) -> Brasília,DF | F27: 45687 | G27: 514.45 | H27: 757 | I27: =Tabela1[[#This Row],[Valor total]]-Tabela1[[#This Row],[Valor custo]] -> 242.55 | J27: =Tabela1[[#This Row],[MARGEM BRUTA]]/Tabela1[[#This Row],[Valor total]] -> 0.32040951 | K27: =VLOOKUP(Tabela1[[#This Row],[Cliente]],'BASE DE CLIENTES'!A:D,4,0) -> EMPRESA SEM MAQUINA | L27: =VLOOKUP(Tabela1[[#This Row],[Cliente]],'BASE DE CLIENTES'!A:E,5,0) -> SETOR INDUSTRIAL (TAGUATINGA)
B28: DILMAR PEREIRA DE SOUZA | C28: =VLOOKUP(Tabela1[[#This Row],[Cliente]],'BASE DE CLIENTES'!A:E,2,0) -> Brasília | D28: =VLOOKUP(Tabela1[[#This Row],[Cliente]],'BASE DE CLIENTES'!A:C,3,0) -> DF | E28: =CONCATENATE(Tabela1[[#This Row],[CIDADE]],",",Tabela1[[#This Row],[UF]]) -> Brasília,DF | F28: 45674 | G28: 8607.27 | H28: 11600 | I28: =Tabela1[[#This Row],[Valor total]]-Tabela1[[#This Row],[Valor custo]] -> 2992.73 | J28: =Tabela1[[#This Row],[MARGEM BRUTA]]/Tabela1[[#This Row],[Valor total]] -> 0.25799397 | K28: =VLOOKUP(Tabela1[[#This Row],[Cliente]],'BASE DE CLIENTES'!A:D,4,0) -> EMPRESA COM MAQUINA | L28: =VLOOKUP(Tabela1[[#This Row],[Cliente]],'BASE DE CLIENTES'!A:E,5,0) -> RIACHO FUNDO II
A29: 3680 | B29: METALURGICA VARELA LTDA | C29: =VLOOKUP(Tabela1[[#This Row],[Cliente]],'BASE DE CLIENTES'!A:E,2,0) -> Brasília | D29: =VLOOKUP(Tabela1[[#This Row],[Cliente]],'BASE DE CLIENTES'!A:C,3,0) -> DF | E29: =CONCATENATE(Tabela1[[#This Row],[CIDADE]],",",Tabela1[[#This Row],[UF]]) -> Brasília,DF | F29: 45687 | G29: 122.74 | H29: 150 | I29: =Tabela1[[#This Row],[Valor total]]-Tabela1[[#This Row],[Valor custo]] -> 27.26 | J29: =Tabela1[[#This Row],[MARGEM BRUTA]]/Tabela1[[#This Row],[Valor total]] -> 0.18173333 | K29: =VLOOKUP(Tabela1[[#This Row],[Cliente]],'BASE DE CLIENTES'!A:D,4,0) -> EMPRESA COM MAQUINA | L29: =VLOOKUP(Tabela1[[#This Row],[Cliente]],'BASE DE CLIENTES'!A:E,5,0) -> TAGUATINGA
A30: 3679 | B30: JAIME FRANCISCO SOARES 27103323100 | C30: =VLOOKUP(Tabela1[[#This Row],[Cliente]],'BASE DE CLIENTES'!A:E,2,0) -> Brasília | D30: =VLOOKUP(Tabela1[[#This Row],[Cliente]],'BASE DE CLIENTES'!A:C,3,0) -> DF | E30: =CONCATENATE(Tabela1[[#This Row],[CIDADE]],",",Tabela1[[#This Row],[UF]]) -> Brasília,DF | F30: 45686 | G30: 268.46 | H30: 550 | I30: =Tabela1[[#This Row],[Valor total]]-Tabela1[[#This Row],[Valor custo]] -> 281.54 | J30: =Tabela1[[#This Row],[MARGEM BRUTA]]/Tabela1[[#This Row],[Valor total]] -> 0.51189091 | K30: =VLOOKUP(Tabela1[[#This Row],[Cliente]],'BASE DE CLIENTES'!A:D,4,0) -> EMPRESA SEM MAQUINA | L30: =VLOOKUP(Tabela1[[#This Row],[Cliente]],'BASE DE CLIENTES'!A:E,5,0) -> SETOR HABITACIONAL VICENTE PIRES
A31: 3678 | B31: FABIO BERNARDO DE ABREU | C31: =VLOOKUP(Tabela1[[#This Row],[Cliente]],'BASE DE CLIENTES'!A:E,2,0) -> Brasília | D31: =VLOOKUP(Tabela1[[#This Row],[Cliente]],'BASE DE CLIENTES'!A:C,3,0) -> DF | E31: =CONCATENATE(Tabela1[[#This Row],[CIDADE]],",",Tabela1[[#This Row],[UF]]) -> Brasília,DF | F31: 45686 | G31: 1543.35 | H31: 2160 | I31: =Tabela1[[#This Row],[Valor total]]-Tabela1[[#This Row],[Valor custo]] -> 616.65 | J31: =Tabela1[[#This Row],[MARGEM BRUTA]]/Tabela1[[#This Row],[Valor total]] -> 0.28548611 | K31: =VLOOKUP(Tabela1[[#This Row],[Cliente]],'BASE DE CLIENTES'!A:D,4,0) -> SERRALHEIRO | L31: =VLOOKUP(Tabela1[[#This Row],[Cliente]],'BASE DE CLIENTES'!A:E,5,0) -> Ceilândia Sul (Ceilândia)
A32: 3677 | B32: JM PORTAS AUTOMATICAS LTDA | C32: =VLOOKUP(Tabela1[[#This Row],[Cliente]],'BASE DE CLIENTES'!A:E,2,0) -> Brasília | D32: =VLOOKUP(Tabela1[[#This Row],[Cliente]],'BASE DE CLIENTES'!A:C,3,0) -> DF | E32: =CONCATENATE(Tabela1[[#This Row],[CIDADE]],",",Tabela1[[#This Row],[UF]]) -> Brasília,DF | F32: 45686 | G32: 439.2 | H32: 620 | I32: =Tabela1[[#This Row],[Valor total]]-Tabela1[[#This Row],[Valor custo]] -> 180.8 | J32: =Tabela1[[#This Row],[MARGEM BRUTA]]/Tabela1[[#This Row],[Valor total]] -> 0.2916129 | K32: =VLOOKUP(Tabela1[[#This Row],[Cliente]],'BASE DE CLIENTES'!A:D,4,0) -> EMPRESA SEM MAQUINA | L32: =VLOOKUP(Tabela1[[#This Row],[Cliente]],'BASE DE CLIENTES'!A:E,5,0) -> SAMAMBAIA
A33: 3676 | B33: FRANCISCO VALDINAR PEREIRA DA SILVA 02490980327 | C33: =VLOOKUP(Tabela1[[#This Row],[Cliente]],'BASE DE CLIENTES'!A:E,2,0) -> Brasília | D33: =VLOOKUP(Tabela1[[#This Row],[Cliente]],'BASE DE CLIENTES'!A:C,3,0) -> DF | E33: =CONCATENATE(Tabela1[[#This Row],[CIDADE]],",",Tabela1[[#This Row],[UF]]) -> Brasília,DF | F33: 45686 | G33: 707.23 | H33: 1450 | I33: =Tabela1[[#This Row],[Valor total]]-Tabela1[[#This Row],[Valor custo]] -> 742.77 | J33: =Tabela1[[#This Row],[MARGEM BRUTA]]/Tabela1[[#This Row],[Valor total]] -> 0.51225517 | K33: =VLOOKUP(Tabela1[[#This Row],[Cliente]],'BASE DE CLIENTES'!A:D,4,0) -> EMPRESA SEM MAQUINA | L33: =VLOOKUP(Tabela1[[#This Row],[Cliente]],'BASE DE CLIENTES'!A:E,5,0) -> RECANTO DAS EMAS
B34: RONALDO ADRIANO DA SILVA SOLSA | C34: =VLOOKUP(Tabela1[[#This Row],[Cliente]],'BASE DE CLIENTES'!A:E,2,0) -> Águas Lindas de Goiás | D34: =VLOOKUP(Tabela1[[#This Row],[Cliente]],'BASE DE CLIENTES'!A:C,3,0) -> GO | E34: =CONCATENATE(Tabela1[[#This Row],[CIDADE]],",",Tabela1[[#This Row],[UF]]) -> Águas Lindas de Goiás,GO | F34: 45671 | G34: 122.74 | H34: 170 | I34: =Tabela1[[#This Row],[Valor total]]-Tabela1[[#This Row],[Valor custo]] -> 47.26 | J34: =Tabela1[[#This Row],[MARGEM BRUTA]]/Tabela1[[#This Row],[Valor total]] -> 0.278 | K34: =VLOOKUP(Tabela1[[#This Row],[Cliente]],'BASE DE CLIENTES'!A:D,4,0) -> SERRALHEIRO | L34: =VLOOKUP(Tabela1[[#This Row],[Cliente]],'BASE DE CLIENTES'!A:E,5,0) -> Águas Lindas de Goiás
A35: 3674 | B35: RAIMUNDO NONATO DA CUNHA 89072898168 | C35: =VLOOKUP(Tabela1[[#This Row],[Cliente]],'BASE DE CLIENTES'!A:E,2,0) -> Brasília | D35: =VLOOKUP(Tabela1[[#This Row],[Cliente]],'BASE DE CLIENTES'!A:C,3,0) -> DF | E35: =CONCATENATE(Tabela1[[#This Row],[CIDADE]],",",Tabela1[[#This Row],[UF]]) -> Brasília,DF | F35: 45686 | G35: 1078.65 | H35: 1585.96 | I35: =Tabela1[[#This Row],[Valor total]]-Tabela1[[#This Row],[Valor custo]] -> 507.31 | J35: =Tabela1[[#This Row],[MARGEM BRUTA]]/Tabela1[[#This Row],[Valor total]] -> 0.31987566 | K35: =VLOOKUP(Tabela1[[#This Row],[Cliente]],'BASE DE CLIENTES'!A:D,4,0) -> SERRALHEIRO | L35: =VLOOKUP(Tabela1[[#This Row],[Cliente]],'BASE DE CLIENTES'!A:E,5,0) -> ARAPOANGA (PLANALTINA)
A36: 3673 | B36: PORTAS DE ACO TROPICAL LTDA | C36: =VLOOKUP(Tabela1[[#This Row],[Cliente]],'BASE DE CLIENTES'!A:E,2,0) -> Brasília | D36: =VLOOKUP(Tabela1[[#This Row],[Cliente]],'BASE DE CLIENTES'!A:C,3,0) -> DF | E36: =CONCATENATE(Tabela1[[#This Row],[CIDADE]],",",Tabela1[[#This Row],[UF]]) -> Brasília,DF | F36: 45686 | G36: 11880.42 | H36: 16400 | I36: =Tabela1[[#This Row],[Valor total]]-Tabela1[[#This Row],[Valor custo]] -> 4519.58 | J36: =Tabela1[[#This Row],[MARGEM BRUTA]]/Tabela1[[#This Row],[Valor total]] -> 0.27558415 | K36: =VLOOKUP(Tabela1[[#This Row],[Cliente]],'BASE DE CLIENTES'!A:D,4,0) -> EMPRESA COM MAQUINA | L36: =VLOOKUP(Tabela1[[#This Row],[Cliente]],'BASE DE CLIENTES'!A:E,5,0) -> SETOR HABITACIONAL VICENTE PIRES
A37: 3672 | B37: 34.505.918 JOSE ANTONIO DUTRA DA SILVA | C37: =VLOOKUP(Tabela1[[#This Row],[Cliente]],'BASE DE CLIENTES'!A:E,2,0) -> Brasília | D37: =VLOOKUP(Tabela1[[#This Row],[Cliente]],'BASE DE CLIENTES'!A:C,3,0) -> DF | E37: =CONCATENATE(Tabela1[[#This Row],[CIDADE]],",",Tabela1[[#This Row],[UF]]) -> Brasília,DF | F37: 45686 | G37: 50 | H37: 60 | I37: =Tabela1[[#This Row],[Valor total]]-Tabela1[[#This Row],[Valor custo]] -> 10 | J37: =Tabela1[[#This Row],[MARGEM BRUTA]]/Tabela1[[#This Row],[Valor total]] -> 0.16666667 | K37: =VLOOKUP(Tabela1[[#This Row],[Cliente]],'BASE DE CLIENTES'!A:D,4,0) -> EMPRESA SEM MAQUINA | L37: =VLOOKUP(Tabela1[[#This Row],[Cliente]],'BASE DE CLIENTES'!A:E,5,0) -> RECANTO DAS EMAS
A38: 3671 | B38: 34.505.918 JOSE ANTONIO DUTRA DA SILVA | C38: =VLOOKUP(Tabela1[[#This Row],[Cliente]],'BASE DE CLIENTES'!A:E,2,0) -> Brasília | D38: =VLOOKUP(Tabela1[[#This Row],[Cliente]],'BASE DE CLIENTES'!A:C,3,0) -> DF | E38: =CONCATENATE(Tabela1[[#This Row],[CIDADE]],",",Tabela1[[#This Row],[UF]]) -> Brasília,DF | F38: 45686 | G38: 1736.13 | H38: 2300 | I38: =Tabela1[[#This Row],[Valor total]]-Tabela1[[#This Row],[Valor custo]] -> 563.87 | J38: =Tabela1[[#This Row],[MARGEM BRUTA]]/Tabela1[[#This Row],[Valor total]] -> 0.24516087 | K38: =VLOOKUP(Tabela1[[#This Row],[Cliente]],'BASE DE CLIENTES'!A:D,4,0) -> EMPRESA SEM MAQUINA | L38: =VLOOKUP(Tabela1[[#This Row],[Cliente]],'BASE DE CLIENTES'!A:E,5,0) -> RECANTO DAS EMAS
B39: MARIO APARECIDO PEREIRA DE BRITO | C39: =VLOOKUP(Tabela1[[#This Row],[Cliente]],'BASE DE CLIENTES'!A:E,2,0) -> Águas Lindas de Goiás | D39: =VLOOKUP(Tabela1[[#This Row],[Cliente]],'BASE DE CLIENTES'!A:C,3,0) -> GO | E39: =CONCATENATE(Tabela1[[#This Row],[CIDADE]],",",Tabela1[[#This Row],[UF]]) -> Águas Lindas de Goiás,GO | F39: 45667 | G39: 1106.09 | H39: 1750 | I39: =Tabela1[[#This Row],[Valor total]]-Tabela1[[#This Row],[Valor custo]] -> 643.91 | J39: =Tabela1[[#This Row],[MARGEM BRUTA]]/Tabela1[[#This Row],[Valor total]] -> 0.36794857 | K39: =VLOOKUP(Tabela1[[#This Row],[Cliente]],'BASE DE CLIENTES'!A:D,4,0) -> SERRALHEIRO | L39: =VLOOKUP(Tabela1[[#This Row],[Cliente]],'BASE DE CLIENTES'!A:E,5,0) -> Águas Lindas de Goiás
B40: Gefferson de Amorim | C40: =VLOOKUP(Tabela1[[#This Row],[Cliente]],'BASE DE CLIENTES'!A:E,2,0) -> Águas Lindas de Goiás | D40: =VLOOKUP(Tabela1[[#This Row],[Cliente]],'BASE DE CLIENTES'!A:C,3,0) -> GO | E40: =CONCATENATE(Tabela1[[#This Row],[CIDADE]],",",Tabela1[[#This Row],[UF]]) -> Águas Lindas de Goiás,GO | F40: 45667 | G40: 1025.87 | H40: 1618 | I40: =Tabela1[[#This Row],[Valor total]]-Tabela1[[#This Row],[Valor custo]] -> 592.13 | J40: =Tabela1[[#This Row],[MARGEM BRUTA]]/Tabela1[[#This Row],[Valor total]] -> 0.36596415 | K40: =VLOOKUP(Tabela1[[#This Row],[Cliente]],'BASE DE CLIENTES'!A:D,4,0) -> SERRALHEIRO | L40: =VLOOKUP(Tabela1[[#This Row],[Cliente]],'BASE DE CLIENTES'!A:E,5,0) -> Águas Lindas de Goiás
...

Sheet BASE DE PRODUTOS
A1: Cód. interno | B1: Cód. de barra | C1: Produto | D1: Quantidade | E1: Custo médio | F1: Custo total | G1: Valor médio | H1: Desconto | I1: Frete | J1: Valor total | K1: Lucro | L1: MÊS | M1: ANO
A2: 2014587755343 | B2: ------ | C2: BOBINA DE AÇO GALVANIZADA GI 0,70 X 136MM | D2: 5014 | E2: 6.93 | F2: 34747.02 | G2: 7.76 | H2: 55.68 | I2: 0 | J2: 38918.02 | K2: 4171 | L2: JANEIRO | M2: 2025
A3: 2098389351200 | B3: ------ | C3: PERFIL AUTOLUBRIFICANTE PVC | D3: 1350 | E3: 2.5 | F3: 3375 | G3: 3.07 | H3: 5.75 | I3: 83.02 | J3: 4139.77 | K3: 764.77 | L3: JANEIRO | M3: 2025
A4: 2033349347800 | B4: ------ | C4: TRAVA LAMINA PRETO DIREITO | D4: 325 | E4: 0.65 | F4: 211.25 | G4: 1.19 | H4: 2.88 | I4: 0 | J4: 387.12 | K4: 175.87 | L4: JANEIRO | M4: 2025
A5: 2006477461908 | B5: ------ | C5: TRAVA LAMINA ESQUERDO | D5: 325 | E5: 0.65 | F5: 211.25 | G5: 1.19 | H5: 2.88 | I5: 0 | J5: 387.12 | K5: 175.87 | L5: JANEIRO | M5: 2025
A6: 2096304900205 | B6: ------ | C6: KIT AC 200 | D6: 228 | E6: 439.2 | F6: 100137.6 | G6: 620.02 | H6: 493.63 | I6: 117.86 | J6: 141364.23 | K6: 41226.63 | L6: JANEIRO | M6: 2025
A7: 2050591800303 | B7: ------ | C7: KIT AC 300 | D7: 172 | E7: 514.45 | F7: 88485.4 | G7: 693.33 | H7: 621.03 | I7: 95.11 | J7: 119252.68 | K7: 30767.28 | L7: JANEIRO | M7: 2025
A8: 2083454607368 | B8: ------ | C8: CONTROLE ANALOGICO | D8: 159 | E8: 10.44 | F8: 1659.96 | G8: 31.03 | H8: 7.07 | I8: 129.22 | J8: 4933.09 | K8: 3273.13 | L8: JANEIRO | M8: 2025
A9: 2084280862006 | B9: ------ | C9: DISCO CORTE CORTG 7 POLEGADAS | D9: 100 | E9: 3.26 | F9: 326 | G9: 5 | H9: 0 | I9: 0 | J9: 500 | K9: 174 | L9: JANEIRO | M9: 2025
A10: 2033856541104 | B10: ------ | C10: DISCO CORTE CORTAG 4 POLEGADAS | D10: 100 | E10: 0.96 | F10: 96 | G10: 0.88 | H10: 0 | I10: 0 | J10: 87.5 | K10: -8.5 | L10: JANEIRO | M10: 2025
A11: 2027684638006 | B11: ------ | C11: KIT AC 400 | D11: 84 | E11: 531.45 | F11: 44641.8 | G11: 756.44 | H11: 233.09 | I11: 0 | J11: 63540.91 | K11: 18899.11 | L11: JANEIRO | M11: 2025
A12: 2089305209842 | B12: ------ | C12: ELETRODO 2,5 MM 350 MM 5KG | D12: 70 | E12: 12.55 | F12: 878.5 | G12: 13.71 | H12: 10 | I12: 0 | J12: 960 | K12: 81.5 | L12: JANEIRO | M12: 2025
A13: 2097826360003 | B13: ------ | C13: KIT AC 200 AUTOTREK | D13: 67 | E13: 409.87 | F13: 27461.29 | G13: 571.94 | H13: 0 | I13: 0 | J13: 38320 | K13: 10858.71 | L13: JANEIRO | M13: 2025
... A1027: 2095883960600 | B1027: ------ | C1027: CHICOTE DC | D1027: 1 | E1027: 0 | F1027: 0 | G1027: 50 | H1027: 0 | I1027: 0 | J1027: 50 | K1027: 50 | L1027: AGOSTO | M1027: 2026

Sheet BASE DE CLIENTES
A1: CLIENTE | B1: CIDADE | C1: UF | D1: CLASSIFICAÇÃO | E1: BAIRRO
A2: WERLES JOSE DA SILVA | B2: Brasília | C2: DF | D2: EMPRESA COM MAQUINA | E2: =VLOOKUP(A2,[1]relatorio_clientes!$C:$Q,15,0) -> 26 DE SETEMBRO
A3: M PORTAS AUTOMATICAS EIRELI | B3: Águas Lindas de Goiás | C3: GO | D3: EMPRESA COM MAQUINA | E3: =B3 -> Águas Lindas de Goiás
A4: MARIO APARECIDO PEREIRA DE BRITO | B4: Águas Lindas de Goiás | C4: GO | D4: SERRALHEIRO | E4: =B4 -> Águas Lindas de Goiás
A5: Gefferson de Amorim | B5: Águas Lindas de Goiás | C5: GO | D5: SERRALHEIRO | E5: =B5 -> Águas Lindas de Goiás
A6: JANILSON DE SOLSA SILVA | B6: Águas Lindas de Goiás | C6: GO | D6: SERRALHEIRO | E6: =B6 -> Águas Lindas de Goiás
A7: REBRASFARMA DROGARIAS LTDA | B7: Águas Lindas de Goiás | C7: GO | D7: SEM CLASSIFICAÇÃO | E7: =B7 -> Águas Lindas de Goiás
A8: EMERSON BARBOSA MUNIZ | B8: Águas Lindas de Goiás | C8: GO | D8: SEM CLASSIFICAÇÃO | E8: =B8 -> Águas Lindas de Goiás
A9: LOTERICA AGUAS LINDAS LTDA | B9: Águas Lindas de Goiás | C9: GO | D9: SEM CLASSIFICAÇÃO | E9: =B9 -> Águas Lindas de Goiás
A10: Orlando Dias Ribeiro | B10: Águas Lindas de Goiás | C10: GO | D10: SERRALHEIRO | E10: =B10 -> Águas Lindas de Goiás
A11: FERNANDES E MELO CONSTRUCOES LTDA | B11: Águas Lindas de Goiás | C11: GO | D11: EMPRESA SEM MAQUINA | E11: =B11 -> Águas Lindas de Goiás
A12: SERRALHERIA E METALUGICA DO GALEGO LTDA | B12: Águas Lindas de Goiás | C12: GO | D12: SERRALHEIRO | E12: =B12 -> Águas Lindas de Goiás
A13: RONALDO ADRIANO DA SILVA SOLSA | B13: Águas Lindas de Goiás | C13: GO | D13: SERRALHEIRO | E13: =B13 -> Águas Lindas de Goiás
A14: 53.840.528 TELMA REIS DE AMORIM MOUSINHO | B14: Águas Lindas de Goiás | C14: GO | D14: EMPRESA SEM MAQUINA | E14: =B14 -> Águas Lindas de Goiás
... A33: COMUNICAR SOCIEDADE COMERCIAL LTDA | B33: Brasilândia de Minas | C33: MG | D33: OUTROS RAMOS | E33: =B33 -> Brasilândia de Minas
A34: SERRALHERIA MORACHIK LTDA | B34: Brasília | C34: DF | D34: EMPRESA COM MAQUINA | E34: =VLOOKUP(A34,[1]relatorio_clientes!$C:$Q,15,0) -> ARAPOANGA (PLANALTINA)
A35: RAIMUNDO NONATO DA CUNHA 89072898168 | B35: Brasília | C35: DF | D35: SERRALHEIRO | E35: =VLOOKUP(A35,[1]relatorio_clientes!$C:$Q,15,0) -> ARAPOANGA (PLANALTINA)
A36: ANTONIO DO SANTOS RIBEIRO | B36: Águas Lindas de Goiás | C36: GO | D36: EMPRESA SEM MAQUINA | E36: =B36 -> Águas Lindas de Goiás
A37: IMPERIO PORTAS DE ACO LTDA | B37: Brasília | C37: DF | D37: EMPRESA COM MAQUINA | E37: ADE ÁGUAS CLARAS
A38: MHS EMPREENDIMENTOS - CONSTRUTORA E INCORPORADORA LTDA | B38: Brasília | C38: DF | D38: SEM CLASSIFICAÇÃO | E38: ADE ÁGUAS CLARAS
A39: LANTERNART LANTERNAGEM E PINTURA LTDA | B39: Brasília | C39: DF | D39: EMPRESA COM MAQUINA | E39: ADE CEILÂNDIA
A40: MV COMERCIO,IMPORTACAO & EXPORTACAO DE PRODUTOS ELETRONICOS LTDA | B40: Brasília | C40: DF | D40: PRODUTOS ELETRONICOS | E40: =VLOOKUP(A40,[1]relatorio_clientes!$C:$Q,15,0) -> AREAL (AGUAS CLARAS)
A41: EQUIP SOUND CAR LTDA | B41: Brasília | C41: DF | D41: SEM CLASSIFICAÇÃO | E41: =VLOOKUP(A41,[1]relatorio_clientes!$C:$Q,15,0) -> AREAL (AGUAS CLARAS)
A42: DG VOLTS ENGENHARIA E OBRAS LTDA | B42: Brasília | C42: DF | D42: SEM CLASSIFICAÇÃO | E42: =VLOOKUP(A42,[1]relatorio_clientes!$C:$Q,15,0) -> AREAL (AGUAS CLARAS)
A43: Agnaldo Evangelista Santos | B43: Brasília | C43: DF | D43: CHAVEIRO | E43: =VLOOKUP(A43,[1]relatorio_clientes!$B:$Q,16,0) -> Areal (Águas Claras)
A44: Santo grau | B44: Brasília | C44: DF | D44: CLIENTE FECHADURA | E44: =VLOOKUP(A44,[1]relatorio_clientes!$B:$Q,16,0) -> Areal (Águas Claras)
A45: ANDRADE E OLIVEIRA REPRESENTACOES | B45: Brasília | C45: DF | D45: SEM CLASSIFICAÇÃO | E45: =VLOOKUP(A45,[1]relatorio_clientes!$B:$Q,16,0) -> Areal (Águas Claras)
A46: GUSTAVO DOS SANTOS SILVA | B46: Brasília | C46: DF | D46: SEM CLASSIFICAÇÃO | E46: =VLOOKUP(A46,[1]relatorio_clientes!$B:$Q,16,0) -> Asa Norte
A47: AURORA BOREAL LUZ COMERCIO E IMPORTACAO LTDA | B47: Brasília | C47: DF | D47: SEM CLASSIFICAÇÃO | E47: =VLOOKUP(A47,[1]relatorio_clientes!$C:$Q,15,0) -> ASA NORTE
A48: PASTELARIA VICOSA LTDA | B48: Brasília | C48: DF | D48: SEM CLASSIFICAÇÃO | E48: =VLOOKUP(A48,[1]relatorio_clientes!$C:$Q,15,0) -> ASA NORTE
A49: DG ENGENHARIA E CONSTRUCOES LTDA | B49: Brasília | C49: DF | D49: SEM CLASSIFICAÇÃO | E49: =VLOOKUP(A49,[1]relatorio_clientes!$C:$Q,15,0) -> ASA SUL
A50: MELO CONSTUCOES E INTALACOES EIRELI-EPP | B50: Brasília | C50: DF | D50: SEM CLASSIFICAÇÃO | E50: =VLOOKUP(A50,[1]relatorio_clientes!$C:$Q,15,0) -> Asa Sul
A51: JK COMERCIO DE FERRAGENS LTDA | B51: Brasília | C51: DF | D51: SEM CLASSIFICAÇÃO | E51: =VLOOKUP(A51,[1]relatorio_clientes!$C:$Q,15,0) -> ASA SUL
A52: E L FRAGNAN SERRALHERIA E SERVICOS EIRELI | B52: Brasília | C52: DF | D52: EMPRESA COM MAQUINA | E52: =VLOOKUP(A52,[1]relatorio_clientes!$C:$Q,15,0) -> CANDANGOLANDIA
A53: SERRALHERIA MAYA LTDA | B53: Brasília | C53: DF | D53: SERRALHEIRO | E53: =VLOOKUP(A53,[1]relatorio_clientes!$C:$Q,15,0) -> CEILANDIA
A54: OTICA E RELOJOARIA VAZ LTDA | B54: Brasília | C54: DF | D54: SEM CLASSIFICAÇÃO | E54: =VLOOKUP(A54,[1]relatorio_clientes!$C:$Q,15,0) -> CEILANDIA
A55: MARCELO DOS SANTOS 58472908100 | B55: Brasília | C55: DF | D55: SERRALHEIRO | E55: =VLOOKUP(A55,[1]relatorio_clientes!$C:$Q,15,0) -> CEILANDIA NORTE
A56: RANGEL SILVA 02665458152 | B56: Brasília | C56: DF | D56: OUTROS RAMOS | E56: =VLOOKUP(A56,[1]relatorio_clientes!$C:$Q,15,0) -> CEILANDIA NORTE
A57: G2 EQUIPAMENTOS & SEGURANCA ELETRONICA LTDA | B57: Brasília | C57: DF | D57: OUTROS RAMOS | E57: =VLOOKUP(A57,[1]relatorio_clientes!$C:$Q,15,0) -> CEILANDIA NORTE (CEILANDIA)
A58: MRA - DISTRIBUIDORA DE PRODUTOS ELETRONICOS LTDA | B58: Brasília | C58: DF | D58: EMPRESA SEM MAQUINA | E58: =VLOOKUP(A58,[1]relatorio_clientes!$C:$Q,15,0) -> CEILANDIA NORTE (CEILANDIA)
...

Sheet LINHA
A1: PRODUTO | B1: CATEGORIA | C1: GRUPO | F1: CATEGORIA | G1: GRUPO
A2: AC 1000 | B2: MOTOR | C2: =VLOOKUP(B2,F:G,2,0) -> LINHA MOTOR | F2: MOTOR | G2: LINHA MOTOR
A3: AC 200 | B3: MOTOR | C3: =VLOOKUP(B3,F:G,2,0) -> LINHA MOTOR | F3: TESTEIRA | G3: LINHA MOTOR
A4: AC 200 AVULSO | B4: MOTOR | C4: =VLOOKUP(B4,F:G,2,0) -> LINHA MOTOR | F4: OUTROS | G4: OUTROS
A5: AC 300 | B5: MOTOR | C5: =VLOOKUP(B5,F:G,2,0) -> LINHA MOTOR | F5: NOBREAK | G5: LINHA MOTOR
A6: AC 400 | B6: MOTOR | C6: =VLOOKUP(B6,F:G,2,0) -> LINHA MOTOR | F6: BOBINA | G6: LINHA MOTOR
A7: AC 500 | B7: MOTOR | C7: =VLOOKUP(B7,F:G,2,0) -> LINHA MOTOR | F7: BOLACHA | G7: LINHA MOTOR
A8: AC 500 AVULSO | B8: MOTOR | C8: =VLOOKUP(B8,F:G,2,0) -> LINHA MOTOR | F8: SOLEIRA | G8: ACESSÓRIOS
A9: Anel da testeira | B9: TESTEIRA | C9: =VLOOKUP(B9,F:G,2,0) -> LINHA MOTOR | F9: BOTOEIRA | G9: LINHA MOTOR
A10: anel para testeira | B10: TESTEIRA | C10: =VLOOKUP(B10,F:G,2,0) -> LINHA MOTOR | F10: CAMISA | G10: OUTROS
A11: Anel proteção da corrente | B11: OUTROS | C11: =VLOOKUP(B11,F:G,2,0) -> OUTROS | F11: CENTRAL | G11: ACESSÓRIOS
A12: anti queda | B12: OUTROS | C12: =VLOOKUP(B12,F:G,2,0) -> OUTROS | F12: CAMISAS/BONÉS | G12: OUTROS
A13: BATERIA P/ NOBREAK | B13: NOBREAK | C13: =VLOOKUP(B13,F:G,2,0) -> LINHA MOTOR | F13: CONTROLE | G13: ACESSÓRIOS
... A45: CENTRAL WI-FI EVO | B45: CENTRAL | C45: =VLOOKUP(B45,F:G,2,0) -> ACESSÓRIOS | F45: CHICOTE | G45: LINHA MOTOR
A46: Chapeu | B46: CAMISAS/BONÉS | C46: =VLOOKUP(B46,F:G,2,0) -> OUTROS
A47: COMBO 01 CENTRAL WIFI, SENSOR DE ABERTURA E ANTIESMAGAMENTO | B47: CENTRAL | C47: =VLOOKUP(B47,F:G,2,0) -> ACESSÓRIOS
A48: COMBO 02 CENTRAL WIFI E SENSOR DE ABERTURA | B48: CENTRAL | C48: =VLOOKUP(B48,F:G,2,0) -> ACESSÓRIOS
A49: COMBO 03 CENTRAL WIFI E ANTIESMAGAMENTO | B49: CENTRAL | C49: =VLOOKUP(B49,F:G,2,0) -> ACESSÓRIOS
A50: CONTATO WI-FI MOTOR DE GARAGEM | B50: CENTRAL | C50: =VLOOKUP(B50,F:G,2,0) -> ACESSÓRIOS
A51: CONTROLE 8 CANAIS | B51: CONTROLE | C51: =VLOOKUP(B51,F:G,2,0) -> ACESSÓRIOS
A52: CONTROLE ANALOGICO | B52: CONTROLE | C52: =VLOOKUP(B52,F:G,2,0) -> ACESSÓRIOS
A53: controle copiador | B53: CONTROLE | C53: =VLOOKUP(B53,F:G,2,0) -> ACESSÓRIOS
A54: CONTROLE COPY EVO | B54: CONTROLE | C54: =VLOOKUP(B54,F:G,2,0) -> ACESSÓRIOS
A55: corrente | B55: CORRENTE | C55: =VLOOKUP(B55,F:G,2,0) -> LINHA MOTOR
A56: CORRENTE (TALHA) 3M | B56: CORRENTE | C56: =VLOOKUP(B56,F:G,2,0) -> LINHA MOTOR
A57: CORRENTE TESTEIRA | B57: TESTEIRA | C57: =VLOOKUP(B57,F:G,2,0) -> LINHA MOTOR
... A210: CENTRAL COPY/DIGITAL | B210: CENTRAL | C210: =VLOOKUP(B210,F:G,2,0) -> ACESSÓRIOS
